ERROR 2022-05-06 09:42:51,005 log   5040 6644 Internal Server Error: /news/addnews/327/
Traceback (most recent call last):
  File "E:\Python_study\News_Portal\news_portal_middleware\venv\lib\site-packages\django\core\handlers\exception.py", line 55, in inner
    response = get_response(request)
  File "E:\Python_study\News_Portal\news_portal_middleware\venv\lib\site-packages\django\core\handlers\base.py", line 197, in _get_response
    response = wrapped_callback(request, *callback_args, **callback_kwargs)
  File "E:\Python_study\News_Portal\news_portal_middleware\venv\lib\site-packages\django\views\generic\base.py", line 84, in view
    return self.dispatch(request, *args, **kwargs)
  File "E:\Python_study\News_Portal\news_portal_middleware\venv\lib\site-packages\django\contrib\auth\mixins.py", line 73, in dispatch
    return super().dispatch(request, *args, **kwargs)
  File "E:\Python_study\News_Portal\news_portal_middleware\venv\lib\site-packages\django\contrib\auth\mixins.py", line 109, in dispatch
    return super().dispatch(request, *args, **kwargs)
  File "E:\Python_study\News_Portal\news_portal_middleware\venv\lib\site-packages\django\views\generic\base.py", line 119, in dispatch
    return handler(request, *args, **kwargs)
  File "E:\Python_study\News_Portal\news_portal_middleware\venv\lib\site-packages\django\views\generic\edit.py", line 208, in post
    return super().post(request, *args, **kwargs)
  File "E:\Python_study\News_Portal\news_portal_middleware\venv\lib\site-packages\django\views\generic\edit.py", line 153, in post
    return self.form_valid(form)
  File "E:\Python_study\News_Portal\news_portal_middleware\venv\lib\site-packages\django\views\generic\edit.py", line 135, in form_valid
    self.object = form.save()
  File "E:\Python_study\News_Portal\news_portal_middleware\venv\lib\site-packages\django\forms\models.py", line 548, in save
    self.instance.save()
  File "E:\Python_study\News_Portal\news_portal_middleware\newsportal\models.py", line 69, in save
    super().save(*args, **kwargs)
  File "E:\Python_study\News_Portal\news_portal_middleware\venv\lib\site-packages\django\db\models\base.py", line 806, in save
    self.save_base(
  File "E:\Python_study\News_Portal\news_portal_middleware\venv\lib\site-packages\django\db\models\base.py", line 872, in save_base
    post_save.send(
  File "E:\Python_study\News_Portal\news_portal_middleware\venv\lib\site-packages\django\dispatch\dispatcher.py", line 176, in send
    return [
  File "E:\Python_study\News_Portal\news_portal_middleware\venv\lib\site-packages\django\dispatch\dispatcher.py", line 177, in <listcomp>
    (receiver, receiver(signal=self, sender=sender, **named))
  File "E:\Python_study\News_Portal\news_portal_middleware\newsportal\signals.py", line 21, in notify_update_post
    new_posts.delay(pk, nw)
  File "E:\Python_study\News_Portal\news_portal_middleware\venv\lib\site-packages\celery\app\task.py", line 425, in delay
    return self.apply_async(args, kwargs)
  File "E:\Python_study\News_Portal\news_portal_middleware\venv\lib\site-packages\celery\app\task.py", line 575, in apply_async
    return app.send_task(
  File "E:\Python_study\News_Portal\news_portal_middleware\venv\lib\site-packages\celery\app\base.py", line 784, in send_task
    with self.producer_or_acquire(producer) as P:
  File "E:\Python_study\News_Portal\news_portal_middleware\venv\lib\site-packages\celery\app\base.py", line 919, in producer_or_acquire
    producer, self.producer_pool.acquire, block=True,
  File "E:\Python_study\News_Portal\news_portal_middleware\venv\lib\site-packages\celery\app\base.py", line 1303, in producer_pool
    return self.amqp.producer_pool
  File "E:\Python_study\News_Portal\news_portal_middleware\venv\lib\site-packages\celery\app\amqp.py", line 583, in producer_pool
    self.app.connection_for_write()]
  File "E:\Python_study\News_Portal\news_portal_middleware\venv\lib\site-packages\celery\app\base.py", line 816, in connection_for_write
    return self._connection(url or self.conf.broker_write_url, **kwargs)
  File "E:\Python_study\News_Portal\news_portal_middleware\venv\lib\site-packages\celery\app\base.py", line 867, in _connection
    return self.amqp.Connection(
  File "E:\Python_study\News_Portal\news_portal_middleware\venv\lib\site-packages\kombu\connection.py", line 181, in __init__
    if not get_transport_cls(transport).can_parse_url:
  File "E:\Python_study\News_Portal\news_portal_middleware\venv\lib\site-packages\kombu\transport\__init__.py", line 85, in get_transport_cls
    _transport_cache[transport] = resolve_transport(transport)
  File "E:\Python_study\News_Portal\news_portal_middleware\venv\lib\site-packages\kombu\transport\__init__.py", line 70, in resolve_transport
    return symbol_by_name(transport)
  File "E:\Python_study\News_Portal\news_portal_middleware\venv\lib\site-packages\kombu\utils\imports.py", line 56, in symbol_by_name
    module = imp(module_name, package=package, **kwargs)
  File "C:\Users\kotko\AppData\Local\Programs\Python\Python39-32\lib\importlib\__init__.py", line 127, in import_module
    return _bootstrap._gcd_import(name[level:], package, level)
  File "<frozen importlib._bootstrap>", line 1030, in _gcd_import
  File "<frozen importlib._bootstrap>", line 1007, in _find_and_load
  File "<frozen importlib._bootstrap>", line 986, in _find_and_load_unlocked
  File "<frozen importlib._bootstrap>", line 680, in _load_unlocked
  File "<frozen importlib._bootstrap_external>", line 790, in exec_module
  File "<frozen importlib._bootstrap>", line 228, in _call_with_frames_removed
  File "E:\Python_study\News_Portal\news_portal_middleware\venv\lib\site-packages\kombu\transport\redis.py", line 262, in <module>
    class PrefixedStrictRedis(GlobalKeyPrefixMixin, redis.Redis):
AttributeError: 'NoneType' object has no attribute 'Redis'
ERROR 2022-05-06 09:42:51,045 basehttp 5040 6644 "POST /news/addnews/327/ HTTP/1.1" 500 242719
ERROR 2022-05-06 09:47:01,464 log   7928 220 Internal Server Error: /news/addnews/327/
Traceback (most recent call last):
  File "E:\Python_study\News_Portal\news_portal_middleware\venv\lib\site-packages\redis\connection.py", line 614, in connect
    sock = self.retry.call_with_retry(
  File "E:\Python_study\News_Portal\news_portal_middleware\venv\lib\site-packages\redis\retry.py", line 45, in call_with_retry
    return do()
  File "E:\Python_study\News_Portal\news_portal_middleware\venv\lib\site-packages\redis\connection.py", line 615, in <lambda>
    lambda: self._connect(), lambda error: self.disconnect(error)
  File "E:\Python_study\News_Portal\news_portal_middleware\venv\lib\site-packages\redis\connection.py", line 680, in _connect
    raise err
  File "E:\Python_study\News_Portal\news_portal_middleware\venv\lib\site-packages\redis\connection.py", line 668, in _connect
    sock.connect(socket_address)
ConnectionRefusedError: [WinError 10061] Подключение не установлено, т.к. конечный компьютер отверг запрос на подключение

During handling of the above exception, another exception occurred:

Traceback (most recent call last):
  File "E:\Python_study\News_Portal\news_portal_middleware\venv\lib\site-packages\celery\backends\redis.py", line 119, in reconnect_on_error
    yield
  File "E:\Python_study\News_Portal\news_portal_middleware\venv\lib\site-packages\celery\backends\redis.py", line 169, in _consume_from
    self._pubsub.subscribe(key)
  File "E:\Python_study\News_Portal\news_portal_middleware\venv\lib\site-packages\redis\client.py", line 1572, in subscribe
    ret_val = self.execute_command("SUBSCRIBE", *new_channels.keys())
  File "E:\Python_study\News_Portal\news_portal_middleware\venv\lib\site-packages\redis\client.py", line 1413, in execute_command
    self.connection = self.connection_pool.get_connection(
  File "E:\Python_study\News_Portal\news_portal_middleware\venv\lib\site-packages\redis\connection.py", line 1386, in get_connection
    connection.connect()
  File "E:\Python_study\News_Portal\news_portal_middleware\venv\lib\site-packages\redis\connection.py", line 620, in connect
    raise ConnectionError(self._error_message(e))
redis.exceptions.ConnectionError: Error 10061 connecting to localhost:6379. Подключение не установлено, т.к. конечный компьютер отверг запрос на подключение.

During handling of the above exception, another exception occurred:

Traceback (most recent call last):
  File "E:\Python_study\News_Portal\news_portal_middleware\venv\lib\site-packages\redis\connection.py", line 614, in connect
    sock = self.retry.call_with_retry(
  File "E:\Python_study\News_Portal\news_portal_middleware\venv\lib\site-packages\redis\retry.py", line 45, in call_with_retry
    return do()
  File "E:\Python_study\News_Portal\news_portal_middleware\venv\lib\site-packages\redis\connection.py", line 615, in <lambda>
    lambda: self._connect(), lambda error: self.disconnect(error)
  File "E:\Python_study\News_Portal\news_portal_middleware\venv\lib\site-packages\redis\connection.py", line 680, in _connect
    raise err
  File "E:\Python_study\News_Portal\news_portal_middleware\venv\lib\site-packages\redis\connection.py", line 668, in _connect
    sock.connect(socket_address)
ConnectionRefusedError: [WinError 10061] Подключение не установлено, т.к. конечный компьютер отверг запрос на подключение

During handling of the above exception, another exception occurred:

Traceback (most recent call last):
  File "E:\Python_study\News_Portal\news_portal_middleware\venv\lib\site-packages\kombu\connection.py", line 446, in _reraise_as_library_errors
    yield
  File "E:\Python_study\News_Portal\news_portal_middleware\venv\lib\site-packages\celery\app\base.py", line 787, in send_task
    self.backend.on_task_call(P, task_id)
  File "E:\Python_study\News_Portal\news_portal_middleware\venv\lib\site-packages\celery\backends\redis.py", line 365, in on_task_call
    self.result_consumer.consume_from(task_id)
  File "E:\Python_study\News_Portal\news_portal_middleware\venv\lib\site-packages\celery\backends\redis.py", line 161, in consume_from
    return self.start(task_id)
  File "E:\Python_study\News_Portal\news_portal_middleware\venv\lib\site-packages\celery\backends\redis.py", line 139, in start
    self._consume_from(initial_task_id)
  File "E:\Python_study\News_Portal\news_portal_middleware\venv\lib\site-packages\celery\backends\redis.py", line 169, in _consume_from
    self._pubsub.subscribe(key)
  File "C:\Users\kotko\AppData\Local\Programs\Python\Python39-32\lib\contextlib.py", line 135, in __exit__
    self.gen.throw(type, value, traceback)
  File "E:\Python_study\News_Portal\news_portal_middleware\venv\lib\site-packages\celery\backends\redis.py", line 122, in reconnect_on_error
    self._ensure(self._reconnect_pubsub, ())
  File "E:\Python_study\News_Portal\news_portal_middleware\venv\lib\site-packages\celery\backends\redis.py", line 376, in ensure
    return retry_over_time(
  File "E:\Python_study\News_Portal\news_portal_middleware\venv\lib\site-packages\kombu\utils\functional.py", line 312, in retry_over_time
    return fun(*args, **kwargs)
  File "E:\Python_study\News_Portal\news_portal_middleware\venv\lib\site-packages\celery\backends\redis.py", line 106, in _reconnect_pubsub
    metas = self.backend.client.mget(self.subscribed_to)
  File "E:\Python_study\News_Portal\news_portal_middleware\venv\lib\site-packages\redis\commands\core.py", line 1792, in mget
    return self.execute_command("MGET", *args, **options)
  File "E:\Python_study\News_Portal\news_portal_middleware\venv\lib\site-packages\redis\client.py", line 1215, in execute_command
    conn = self.connection or pool.get_connection(command_name, **options)
  File "E:\Python_study\News_Portal\news_portal_middleware\venv\lib\site-packages\redis\connection.py", line 1386, in get_connection
    connection.connect()
  File "E:\Python_study\News_Portal\news_portal_middleware\venv\lib\site-packages\redis\connection.py", line 620, in connect
    raise ConnectionError(self._error_message(e))
redis.exceptions.ConnectionError: Error 10061 connecting to localhost:6379. Подключение не установлено, т.к. конечный компьютер отверг запрос на подключение.

The above exception was the direct cause of the following exception:

Traceback (most recent call last):
  File "E:\Python_study\News_Portal\news_portal_middleware\venv\lib\site-packages\django\core\handlers\exception.py", line 55, in inner
    response = get_response(request)
  File "E:\Python_study\News_Portal\news_portal_middleware\venv\lib\site-packages\django\core\handlers\base.py", line 197, in _get_response
    response = wrapped_callback(request, *callback_args, **callback_kwargs)
  File "E:\Python_study\News_Portal\news_portal_middleware\venv\lib\site-packages\django\views\generic\base.py", line 84, in view
    return self.dispatch(request, *args, **kwargs)
  File "E:\Python_study\News_Portal\news_portal_middleware\venv\lib\site-packages\django\contrib\auth\mixins.py", line 73, in dispatch
    return super().dispatch(request, *args, **kwargs)
  File "E:\Python_study\News_Portal\news_portal_middleware\venv\lib\site-packages\django\contrib\auth\mixins.py", line 109, in dispatch
    return super().dispatch(request, *args, **kwargs)
  File "E:\Python_study\News_Portal\news_portal_middleware\venv\lib\site-packages\django\views\generic\base.py", line 119, in dispatch
    return handler(request, *args, **kwargs)
  File "E:\Python_study\News_Portal\news_portal_middleware\venv\lib\site-packages\django\views\generic\edit.py", line 208, in post
    return super().post(request, *args, **kwargs)
  File "E:\Python_study\News_Portal\news_portal_middleware\venv\lib\site-packages\django\views\generic\edit.py", line 153, in post
    return self.form_valid(form)
  File "E:\Python_study\News_Portal\news_portal_middleware\venv\lib\site-packages\django\views\generic\edit.py", line 135, in form_valid
    self.object = form.save()
  File "E:\Python_study\News_Portal\news_portal_middleware\venv\lib\site-packages\django\forms\models.py", line 548, in save
    self.instance.save()
  File "E:\Python_study\News_Portal\news_portal_middleware\newsportal\models.py", line 69, in save
    super().save(*args, **kwargs)
  File "E:\Python_study\News_Portal\news_portal_middleware\venv\lib\site-packages\django\db\models\base.py", line 806, in save
    self.save_base(
  File "E:\Python_study\News_Portal\news_portal_middleware\venv\lib\site-packages\django\db\models\base.py", line 872, in save_base
    post_save.send(
  File "E:\Python_study\News_Portal\news_portal_middleware\venv\lib\site-packages\django\dispatch\dispatcher.py", line 176, in send
    return [
  File "E:\Python_study\News_Portal\news_portal_middleware\venv\lib\site-packages\django\dispatch\dispatcher.py", line 177, in <listcomp>
    (receiver, receiver(signal=self, sender=sender, **named))
  File "E:\Python_study\News_Portal\news_portal_middleware\newsportal\signals.py", line 21, in notify_update_post
    new_posts.delay(pk, nw)
  File "E:\Python_study\News_Portal\news_portal_middleware\venv\lib\site-packages\celery\app\task.py", line 425, in delay
    return self.apply_async(args, kwargs)
  File "E:\Python_study\News_Portal\news_portal_middleware\venv\lib\site-packages\celery\app\task.py", line 575, in apply_async
    return app.send_task(
  File "E:\Python_study\News_Portal\news_portal_middleware\venv\lib\site-packages\celery\app\base.py", line 788, in send_task
    amqp.send_task_message(P, name, message, **options)
  File "C:\Users\kotko\AppData\Local\Programs\Python\Python39-32\lib\contextlib.py", line 135, in __exit__
    self.gen.throw(type, value, traceback)
  File "E:\Python_study\News_Portal\news_portal_middleware\venv\lib\site-packages\kombu\connection.py", line 450, in _reraise_as_library_errors
    raise ConnectionError(str(exc)) from exc
kombu.exceptions.OperationalError: Error 10061 connecting to localhost:6379. Подключение не установлено, т.к. конечный компьютер отверг запрос на подключение.
2022-05-16 09:19:03,616 : ERROR - Internal Server Error: / - D:\PythonStudy\News_Portal\venv\lib\site-packages\django\utils\log.py - (<class 'django.template.exceptions.TemplateSyntaxError'>, TemplateSyntaxError("Invalid block tag on line 10: 'trans', expected 'endblock'. Did you forget to register or load this tag?"), <traceback object at 0x000001AC4A83A040>)
Traceback (most recent call last):
  File "D:\PythonStudy\News_Portal\venv\lib\site-packages\django\template\base.py", line 500, in parse
    compile_func = self.tags[command]
KeyError: 'trans'

During handling of the above exception, another exception occurred:

Traceback (most recent call last):
  File "D:\PythonStudy\News_Portal\venv\lib\site-packages\django\core\handlers\exception.py", line 47, in inner
    response = get_response(request)
  File "D:\PythonStudy\News_Portal\venv\lib\site-packages\django\core\handlers\base.py", line 204, in _get_response
    response = response.render()
  File "D:\PythonStudy\News_Portal\venv\lib\site-packages\django\template\response.py", line 105, in render
    self.content = self.rendered_content
  File "D:\PythonStudy\News_Portal\venv\lib\site-packages\django\template\response.py", line 81, in rendered_content
    template = self.resolve_template(self.template_name)
  File "D:\PythonStudy\News_Portal\venv\lib\site-packages\django\template\response.py", line 63, in resolve_template
    return select_template(template, using=self.using)
  File "D:\PythonStudy\News_Portal\venv\lib\site-packages\django\template\loader.py", line 42, in select_template
    return engine.get_template(template_name)
  File "D:\PythonStudy\News_Portal\venv\lib\site-packages\django\template\backends\django.py", line 34, in get_template
    return Template(self.engine.get_template(template_name), self)
  File "D:\PythonStudy\News_Portal\venv\lib\site-packages\django\template\engine.py", line 163, in get_template
    template, origin = self.find_template(template_name)
  File "D:\PythonStudy\News_Portal\venv\lib\site-packages\django\template\engine.py", line 145, in find_template
    template = loader.get_template(name, skip=skip)
  File "D:\PythonStudy\News_Portal\venv\lib\site-packages\django\template\loaders\base.py", line 29, in get_template
    return Template(
  File "D:\PythonStudy\News_Portal\venv\lib\site-packages\django\template\base.py", line 155, in __init__
    self.nodelist = self.compile_nodelist()
  File "D:\PythonStudy\News_Portal\venv\lib\site-packages\django\template\base.py", line 199, in compile_nodelist
    return parser.parse()
  File "D:\PythonStudy\News_Portal\venv\lib\site-packages\django\template\base.py", line 508, in parse
    raise self.error(token, e)
  File "D:\PythonStudy\News_Portal\venv\lib\site-packages\django\template\base.py", line 506, in parse
    compiled_result = compile_func(self, token)
  File "D:\PythonStudy\News_Portal\venv\lib\site-packages\django\template\loader_tags.py", line 284, in do_extends
    nodelist = parser.parse()
  File "D:\PythonStudy\News_Portal\venv\lib\site-packages\django\template\base.py", line 508, in parse
    raise self.error(token, e)
  File "D:\PythonStudy\News_Portal\venv\lib\site-packages\django\template\base.py", line 506, in parse
    compiled_result = compile_func(self, token)
  File "D:\PythonStudy\News_Portal\venv\lib\site-packages\django\template\loader_tags.py", line 222, in do_block
    nodelist = parser.parse(('endblock',))
  File "D:\PythonStudy\News_Portal\venv\lib\site-packages\django\template\base.py", line 502, in parse
    self.invalid_block_tag(token, command, parse_until)
  File "D:\PythonStudy\News_Portal\venv\lib\site-packages\django\template\base.py", line 552, in invalid_block_tag
    raise self.error(
django.template.exceptions.TemplateSyntaxError: Invalid block tag on line 10: 'trans', expected 'endblock'. Did you forget to register or load this tag?
2022-05-16 09:19:03,650 : ERROR - "GET / HTTP/1.1" 500 159802 - D:\PythonStudy\News_Portal\venv\lib\site-packages\django\core\servers\basehttp.py - None
2022-05-16 09:26:54,526 : ERROR - Internal Server Error: /news/ - D:\PythonStudy\News_Portal\venv\lib\site-packages\django\utils\log.py - (<class 'django.template.exceptions.TemplateSyntaxError'>, TemplateSyntaxError("Invalid block tag on line 6: 'trans', expected 'endblock'. Did you forget to register or load this tag?"), <traceback object at 0x00000287EB8FBA80>)
Traceback (most recent call last):
  File "D:\PythonStudy\News_Portal\venv\lib\site-packages\django\template\base.py", line 500, in parse
    compile_func = self.tags[command]
KeyError: 'trans'

During handling of the above exception, another exception occurred:

Traceback (most recent call last):
  File "D:\PythonStudy\News_Portal\venv\lib\site-packages\django\core\handlers\exception.py", line 47, in inner
    response = get_response(request)
  File "D:\PythonStudy\News_Portal\venv\lib\site-packages\django\core\handlers\base.py", line 204, in _get_response
    response = response.render()
  File "D:\PythonStudy\News_Portal\venv\lib\site-packages\django\template\response.py", line 105, in render
    self.content = self.rendered_content
  File "D:\PythonStudy\News_Portal\venv\lib\site-packages\django\template\response.py", line 81, in rendered_content
    template = self.resolve_template(self.template_name)
  File "D:\PythonStudy\News_Portal\venv\lib\site-packages\django\template\response.py", line 63, in resolve_template
    return select_template(template, using=self.using)
  File "D:\PythonStudy\News_Portal\venv\lib\site-packages\django\template\loader.py", line 42, in select_template
    return engine.get_template(template_name)
  File "D:\PythonStudy\News_Portal\venv\lib\site-packages\django\template\backends\django.py", line 34, in get_template
    return Template(self.engine.get_template(template_name), self)
  File "D:\PythonStudy\News_Portal\venv\lib\site-packages\django\template\engine.py", line 163, in get_template
    template, origin = self.find_template(template_name)
  File "D:\PythonStudy\News_Portal\venv\lib\site-packages\django\template\engine.py", line 145, in find_template
    template = loader.get_template(name, skip=skip)
  File "D:\PythonStudy\News_Portal\venv\lib\site-packages\django\template\loaders\base.py", line 29, in get_template
    return Template(
  File "D:\PythonStudy\News_Portal\venv\lib\site-packages\django\template\base.py", line 155, in __init__
    self.nodelist = self.compile_nodelist()
  File "D:\PythonStudy\News_Portal\venv\lib\site-packages\django\template\base.py", line 199, in compile_nodelist
    return parser.parse()
  File "D:\PythonStudy\News_Portal\venv\lib\site-packages\django\template\base.py", line 508, in parse
    raise self.error(token, e)
  File "D:\PythonStudy\News_Portal\venv\lib\site-packages\django\template\base.py", line 506, in parse
    compiled_result = compile_func(self, token)
  File "D:\PythonStudy\News_Portal\venv\lib\site-packages\django\template\loader_tags.py", line 284, in do_extends
    nodelist = parser.parse()
  File "D:\PythonStudy\News_Portal\venv\lib\site-packages\django\template\base.py", line 508, in parse
    raise self.error(token, e)
  File "D:\PythonStudy\News_Portal\venv\lib\site-packages\django\template\base.py", line 506, in parse
    compiled_result = compile_func(self, token)
  File "D:\PythonStudy\News_Portal\venv\lib\site-packages\django\template\loader_tags.py", line 222, in do_block
    nodelist = parser.parse(('endblock',))
  File "D:\PythonStudy\News_Portal\venv\lib\site-packages\django\template\base.py", line 502, in parse
    self.invalid_block_tag(token, command, parse_until)
  File "D:\PythonStudy\News_Portal\venv\lib\site-packages\django\template\base.py", line 552, in invalid_block_tag
    raise self.error(
django.template.exceptions.TemplateSyntaxError: Invalid block tag on line 6: 'trans', expected 'endblock'. Did you forget to register or load this tag?
2022-05-16 09:26:54,529 : ERROR - "GET /news/ HTTP/1.1" 500 206583 - D:\PythonStudy\News_Portal\venv\lib\site-packages\django\core\servers\basehttp.py - None
2022-05-16 09:45:15,569 : ERROR - Internal Server Error: /news/search/ - D:\PythonStudy\News_Portal\venv\lib\site-packages\django\utils\log.py - (<class 'django.template.exceptions.TemplateSyntaxError'>, TemplateSyntaxError("Invalid block tag on line 12: 'trans', expected 'endblock'. Did you forget to register or load this tag?"), <traceback object at 0x000002C0C2162680>)
Traceback (most recent call last):
  File "D:\PythonStudy\News_Portal\venv\lib\site-packages\django\template\base.py", line 500, in parse
    compile_func = self.tags[command]
KeyError: 'trans'

During handling of the above exception, another exception occurred:

Traceback (most recent call last):
  File "D:\PythonStudy\News_Portal\venv\lib\site-packages\django\core\handlers\exception.py", line 47, in inner
    response = get_response(request)
  File "D:\PythonStudy\News_Portal\venv\lib\site-packages\django\core\handlers\base.py", line 204, in _get_response
    response = response.render()
  File "D:\PythonStudy\News_Portal\venv\lib\site-packages\django\template\response.py", line 105, in render
    self.content = self.rendered_content
  File "D:\PythonStudy\News_Portal\venv\lib\site-packages\django\template\response.py", line 81, in rendered_content
    template = self.resolve_template(self.template_name)
  File "D:\PythonStudy\News_Portal\venv\lib\site-packages\django\template\response.py", line 63, in resolve_template
    return select_template(template, using=self.using)
  File "D:\PythonStudy\News_Portal\venv\lib\site-packages\django\template\loader.py", line 42, in select_template
    return engine.get_template(template_name)
  File "D:\PythonStudy\News_Portal\venv\lib\site-packages\django\template\backends\django.py", line 34, in get_template
    return Template(self.engine.get_template(template_name), self)
  File "D:\PythonStudy\News_Portal\venv\lib\site-packages\django\template\engine.py", line 163, in get_template
    template, origin = self.find_template(template_name)
  File "D:\PythonStudy\News_Portal\venv\lib\site-packages\django\template\engine.py", line 145, in find_template
    template = loader.get_template(name, skip=skip)
  File "D:\PythonStudy\News_Portal\venv\lib\site-packages\django\template\loaders\base.py", line 29, in get_template
    return Template(
  File "D:\PythonStudy\News_Portal\venv\lib\site-packages\django\template\base.py", line 155, in __init__
    self.nodelist = self.compile_nodelist()
  File "D:\PythonStudy\News_Portal\venv\lib\site-packages\django\template\base.py", line 199, in compile_nodelist
    return parser.parse()
  File "D:\PythonStudy\News_Portal\venv\lib\site-packages\django\template\base.py", line 508, in parse
    raise self.error(token, e)
  File "D:\PythonStudy\News_Portal\venv\lib\site-packages\django\template\base.py", line 506, in parse
    compiled_result = compile_func(self, token)
  File "D:\PythonStudy\News_Portal\venv\lib\site-packages\django\template\loader_tags.py", line 284, in do_extends
    nodelist = parser.parse()
  File "D:\PythonStudy\News_Portal\venv\lib\site-packages\django\template\base.py", line 508, in parse
    raise self.error(token, e)
  File "D:\PythonStudy\News_Portal\venv\lib\site-packages\django\template\base.py", line 506, in parse
    compiled_result = compile_func(self, token)
  File "D:\PythonStudy\News_Portal\venv\lib\site-packages\django\template\loader_tags.py", line 222, in do_block
    nodelist = parser.parse(('endblock',))
  File "D:\PythonStudy\News_Portal\venv\lib\site-packages\django\template\base.py", line 502, in parse
    self.invalid_block_tag(token, command, parse_until)
  File "D:\PythonStudy\News_Portal\venv\lib\site-packages\django\template\base.py", line 552, in invalid_block_tag
    raise self.error(
django.template.exceptions.TemplateSyntaxError: Invalid block tag on line 12: 'trans', expected 'endblock'. Did you forget to register or load this tag?
2022-05-16 09:45:15,572 : ERROR - "GET /news/search/ HTTP/1.1" 500 211431 - D:\PythonStudy\News_Portal\venv\lib\site-packages\django\core\servers\basehttp.py - None
2022-05-16 17:23:05,991 : ERROR - Internal Server Error: /admin/newsportal/post/328/change/ - D:\PythonStudy\News_Portal\venv\lib\site-packages\django\utils\log.py - (<class 'kombu.exceptions.OperationalError'>, OperationalError('Error 10061 connecting to localhost:6379. Подключение не установлено, т.к. конечный компьютер отверг запрос на подключение.'), <traceback object at 0x000001FFFBE50B40>)
Traceback (most recent call last):
  File "D:\PythonStudy\News_Portal\venv\lib\site-packages\redis\connection.py", line 607, in connect
    sock = self.retry.call_with_retry(
  File "D:\PythonStudy\News_Portal\venv\lib\site-packages\redis\retry.py", line 45, in call_with_retry
    return do()
  File "D:\PythonStudy\News_Portal\venv\lib\site-packages\redis\connection.py", line 608, in <lambda>
    lambda: self._connect(), lambda error: self.disconnect(error)
  File "D:\PythonStudy\News_Portal\venv\lib\site-packages\redis\connection.py", line 673, in _connect
    raise err
  File "D:\PythonStudy\News_Portal\venv\lib\site-packages\redis\connection.py", line 661, in _connect
    sock.connect(socket_address)
ConnectionRefusedError: [WinError 10061] Подключение не установлено, т.к. конечный компьютер отверг запрос на подключение

During handling of the above exception, another exception occurred:

Traceback (most recent call last):
  File "D:\PythonStudy\News_Portal\venv\lib\site-packages\celery\backends\redis.py", line 119, in reconnect_on_error
    yield
  File "D:\PythonStudy\News_Portal\venv\lib\site-packages\celery\backends\redis.py", line 169, in _consume_from
    self._pubsub.subscribe(key)
  File "D:\PythonStudy\News_Portal\venv\lib\site-packages\redis\client.py", line 1530, in subscribe
    ret_val = self.execute_command("SUBSCRIBE", *new_channels.keys())
  File "D:\PythonStudy\News_Portal\venv\lib\site-packages\redis\client.py", line 1371, in execute_command
    self.connection = self.connection_pool.get_connection(
  File "D:\PythonStudy\News_Portal\venv\lib\site-packages\redis\connection.py", line 1370, in get_connection
    connection.connect()
  File "D:\PythonStudy\News_Portal\venv\lib\site-packages\redis\connection.py", line 613, in connect
    raise ConnectionError(self._error_message(e))
redis.exceptions.ConnectionError: Error 10061 connecting to localhost:6379. Подключение не установлено, т.к. конечный компьютер отверг запрос на подключение.

During handling of the above exception, another exception occurred:

Traceback (most recent call last):
  File "D:\PythonStudy\News_Portal\venv\lib\site-packages\redis\connection.py", line 607, in connect
    sock = self.retry.call_with_retry(
  File "D:\PythonStudy\News_Portal\venv\lib\site-packages\redis\retry.py", line 45, in call_with_retry
    return do()
  File "D:\PythonStudy\News_Portal\venv\lib\site-packages\redis\connection.py", line 608, in <lambda>
    lambda: self._connect(), lambda error: self.disconnect(error)
  File "D:\PythonStudy\News_Portal\venv\lib\site-packages\redis\connection.py", line 673, in _connect
    raise err
  File "D:\PythonStudy\News_Portal\venv\lib\site-packages\redis\connection.py", line 661, in _connect
    sock.connect(socket_address)
ConnectionRefusedError: [WinError 10061] Подключение не установлено, т.к. конечный компьютер отверг запрос на подключение

During handling of the above exception, another exception occurred:

Traceback (most recent call last):
  File "D:\PythonStudy\News_Portal\venv\lib\site-packages\kombu\connection.py", line 446, in _reraise_as_library_errors
    yield
  File "D:\PythonStudy\News_Portal\venv\lib\site-packages\celery\app\base.py", line 787, in send_task
    self.backend.on_task_call(P, task_id)
  File "D:\PythonStudy\News_Portal\venv\lib\site-packages\celery\backends\redis.py", line 365, in on_task_call
    self.result_consumer.consume_from(task_id)
  File "D:\PythonStudy\News_Portal\venv\lib\site-packages\celery\backends\redis.py", line 161, in consume_from
    return self.start(task_id)
  File "D:\PythonStudy\News_Portal\venv\lib\site-packages\celery\backends\redis.py", line 139, in start
    self._consume_from(initial_task_id)
  File "D:\PythonStudy\News_Portal\venv\lib\site-packages\celery\backends\redis.py", line 169, in _consume_from
    self._pubsub.subscribe(key)
  File "C:\Users\kotko\AppData\Local\Programs\Python\Python39\lib\contextlib.py", line 135, in __exit__
    self.gen.throw(type, value, traceback)
  File "D:\PythonStudy\News_Portal\venv\lib\site-packages\celery\backends\redis.py", line 122, in reconnect_on_error
    self._ensure(self._reconnect_pubsub, ())
  File "D:\PythonStudy\News_Portal\venv\lib\site-packages\celery\backends\redis.py", line 376, in ensure
    return retry_over_time(
  File "D:\PythonStudy\News_Portal\venv\lib\site-packages\kombu\utils\functional.py", line 312, in retry_over_time
    return fun(*args, **kwargs)
  File "D:\PythonStudy\News_Portal\venv\lib\site-packages\celery\backends\redis.py", line 106, in _reconnect_pubsub
    metas = self.backend.client.mget(self.subscribed_to)
  File "D:\PythonStudy\News_Portal\venv\lib\site-packages\redis\commands\core.py", line 1404, in mget
    return self.execute_command("MGET", *args, **options)
  File "D:\PythonStudy\News_Portal\venv\lib\site-packages\redis\client.py", line 1173, in execute_command
    conn = self.connection or pool.get_connection(command_name, **options)
  File "D:\PythonStudy\News_Portal\venv\lib\site-packages\redis\connection.py", line 1370, in get_connection
    connection.connect()
  File "D:\PythonStudy\News_Portal\venv\lib\site-packages\redis\connection.py", line 613, in connect
    raise ConnectionError(self._error_message(e))
redis.exceptions.ConnectionError: Error 10061 connecting to localhost:6379. Подключение не установлено, т.к. конечный компьютер отверг запрос на подключение.

The above exception was the direct cause of the following exception:

Traceback (most recent call last):
  File "D:\PythonStudy\News_Portal\venv\lib\site-packages\django\core\handlers\exception.py", line 47, in inner
    response = get_response(request)
  File "D:\PythonStudy\News_Portal\venv\lib\site-packages\django\core\handlers\base.py", line 181, in _get_response
    response = wrapped_callback(request, *callback_args, **callback_kwargs)
  File "D:\PythonStudy\News_Portal\venv\lib\site-packages\django\contrib\admin\options.py", line 622, in wrapper
    return self.admin_site.admin_view(view)(*args, **kwargs)
  File "D:\PythonStudy\News_Portal\venv\lib\site-packages\django\utils\decorators.py", line 130, in _wrapped_view
    response = view_func(request, *args, **kwargs)
  File "D:\PythonStudy\News_Portal\venv\lib\site-packages\django\views\decorators\cache.py", line 57, in _wrapped_view_func
    response = view_func(request, *args, **kwargs)
  File "D:\PythonStudy\News_Portal\venv\lib\site-packages\django\contrib\admin\sites.py", line 236, in inner
    return view(request, *args, **kwargs)
  File "D:\PythonStudy\News_Portal\venv\lib\site-packages\django\contrib\admin\options.py", line 1673, in change_view
    return self.changeform_view(request, object_id, form_url, extra_context)
  File "D:\PythonStudy\News_Portal\venv\lib\site-packages\django\utils\decorators.py", line 43, in _wrapper
    return bound_method(*args, **kwargs)
  File "D:\PythonStudy\News_Portal\venv\lib\site-packages\django\utils\decorators.py", line 130, in _wrapped_view
    response = view_func(request, *args, **kwargs)
  File "D:\PythonStudy\News_Portal\venv\lib\site-packages\django\contrib\admin\options.py", line 1549, in changeform_view
    return self._changeform_view(request, object_id, form_url, extra_context)
  File "D:\PythonStudy\News_Portal\venv\lib\site-packages\django\contrib\admin\options.py", line 1599, in _changeform_view
    self.save_model(request, new_object, form, not add)
  File "D:\PythonStudy\News_Portal\venv\lib\site-packages\django\contrib\admin\options.py", line 1108, in save_model
    obj.save()
  File "D:\PythonStudy\News_Portal\news_portal\newsportal\models.py", line 71, in save
    super().save(*args, **kwargs)
  File "D:\PythonStudy\News_Portal\venv\lib\site-packages\django\db\models\base.py", line 743, in save
    self.save_base(using=using, force_insert=force_insert,
  File "D:\PythonStudy\News_Portal\venv\lib\site-packages\django\db\models\base.py", line 791, in save_base
    post_save.send(
  File "D:\PythonStudy\News_Portal\venv\lib\site-packages\django\dispatch\dispatcher.py", line 170, in send
    return [
  File "D:\PythonStudy\News_Portal\venv\lib\site-packages\django\dispatch\dispatcher.py", line 171, in <listcomp>
    (receiver, receiver(signal=self, sender=sender, **named))
  File "D:\PythonStudy\News_Portal\news_portal\newsportal\signals.py", line 21, in notify_update_post
    new_posts.delay(pk, nw)
  File "D:\PythonStudy\News_Portal\venv\lib\site-packages\celery\app\task.py", line 425, in delay
    return self.apply_async(args, kwargs)
  File "D:\PythonStudy\News_Portal\venv\lib\site-packages\celery\app\task.py", line 575, in apply_async
    return app.send_task(
  File "D:\PythonStudy\News_Portal\venv\lib\site-packages\celery\app\base.py", line 788, in send_task
    amqp.send_task_message(P, name, message, **options)
  File "C:\Users\kotko\AppData\Local\Programs\Python\Python39\lib\contextlib.py", line 135, in __exit__
    self.gen.throw(type, value, traceback)
  File "D:\PythonStudy\News_Portal\venv\lib\site-packages\kombu\connection.py", line 450, in _reraise_as_library_errors
    raise ConnectionError(str(exc)) from exc
kombu.exceptions.OperationalError: Error 10061 connecting to localhost:6379. Подключение не установлено, т.к. конечный компьютер отверг запрос на подключение.
2022-05-16 17:27:59,957 : ERROR - Internal Server Error: /admin/newsportal/post/328/change/ - D:\PythonStudy\News_Portal\venv\lib\site-packages\django\utils\log.py - (<class 'kombu.exceptions.OperationalError'>, OperationalError('Error 10061 connecting to localhost:6379. Подключение не установлено, т.к. конечный компьютер отверг запрос на подключение.'), <traceback object at 0x0000022B093BB280>)
Traceback (most recent call last):
  File "D:\PythonStudy\News_Portal\venv\lib\site-packages\redis\connection.py", line 607, in connect
    sock = self.retry.call_with_retry(
  File "D:\PythonStudy\News_Portal\venv\lib\site-packages\redis\retry.py", line 45, in call_with_retry
    return do()
  File "D:\PythonStudy\News_Portal\venv\lib\site-packages\redis\connection.py", line 608, in <lambda>
    lambda: self._connect(), lambda error: self.disconnect(error)
  File "D:\PythonStudy\News_Portal\venv\lib\site-packages\redis\connection.py", line 673, in _connect
    raise err
  File "D:\PythonStudy\News_Portal\venv\lib\site-packages\redis\connection.py", line 661, in _connect
    sock.connect(socket_address)
ConnectionRefusedError: [WinError 10061] Подключение не установлено, т.к. конечный компьютер отверг запрос на подключение

During handling of the above exception, another exception occurred:

Traceback (most recent call last):
  File "D:\PythonStudy\News_Portal\venv\lib\site-packages\celery\backends\redis.py", line 119, in reconnect_on_error
    yield
  File "D:\PythonStudy\News_Portal\venv\lib\site-packages\celery\backends\redis.py", line 169, in _consume_from
    self._pubsub.subscribe(key)
  File "D:\PythonStudy\News_Portal\venv\lib\site-packages\redis\client.py", line 1530, in subscribe
    ret_val = self.execute_command("SUBSCRIBE", *new_channels.keys())
  File "D:\PythonStudy\News_Portal\venv\lib\site-packages\redis\client.py", line 1371, in execute_command
    self.connection = self.connection_pool.get_connection(
  File "D:\PythonStudy\News_Portal\venv\lib\site-packages\redis\connection.py", line 1370, in get_connection
    connection.connect()
  File "D:\PythonStudy\News_Portal\venv\lib\site-packages\redis\connection.py", line 613, in connect
    raise ConnectionError(self._error_message(e))
redis.exceptions.ConnectionError: Error 10061 connecting to localhost:6379. Подключение не установлено, т.к. конечный компьютер отверг запрос на подключение.

During handling of the above exception, another exception occurred:

Traceback (most recent call last):
  File "D:\PythonStudy\News_Portal\venv\lib\site-packages\redis\connection.py", line 607, in connect
    sock = self.retry.call_with_retry(
  File "D:\PythonStudy\News_Portal\venv\lib\site-packages\redis\retry.py", line 45, in call_with_retry
    return do()
  File "D:\PythonStudy\News_Portal\venv\lib\site-packages\redis\connection.py", line 608, in <lambda>
    lambda: self._connect(), lambda error: self.disconnect(error)
  File "D:\PythonStudy\News_Portal\venv\lib\site-packages\redis\connection.py", line 673, in _connect
    raise err
  File "D:\PythonStudy\News_Portal\venv\lib\site-packages\redis\connection.py", line 661, in _connect
    sock.connect(socket_address)
ConnectionRefusedError: [WinError 10061] Подключение не установлено, т.к. конечный компьютер отверг запрос на подключение

During handling of the above exception, another exception occurred:

Traceback (most recent call last):
  File "D:\PythonStudy\News_Portal\venv\lib\site-packages\kombu\connection.py", line 446, in _reraise_as_library_errors
    yield
  File "D:\PythonStudy\News_Portal\venv\lib\site-packages\celery\app\base.py", line 787, in send_task
    self.backend.on_task_call(P, task_id)
  File "D:\PythonStudy\News_Portal\venv\lib\site-packages\celery\backends\redis.py", line 365, in on_task_call
    self.result_consumer.consume_from(task_id)
  File "D:\PythonStudy\News_Portal\venv\lib\site-packages\celery\backends\redis.py", line 161, in consume_from
    return self.start(task_id)
  File "D:\PythonStudy\News_Portal\venv\lib\site-packages\celery\backends\redis.py", line 139, in start
    self._consume_from(initial_task_id)
  File "D:\PythonStudy\News_Portal\venv\lib\site-packages\celery\backends\redis.py", line 169, in _consume_from
    self._pubsub.subscribe(key)
  File "C:\Users\kotko\AppData\Local\Programs\Python\Python39\lib\contextlib.py", line 135, in __exit__
    self.gen.throw(type, value, traceback)
  File "D:\PythonStudy\News_Portal\venv\lib\site-packages\celery\backends\redis.py", line 122, in reconnect_on_error
    self._ensure(self._reconnect_pubsub, ())
  File "D:\PythonStudy\News_Portal\venv\lib\site-packages\celery\backends\redis.py", line 376, in ensure
    return retry_over_time(
  File "D:\PythonStudy\News_Portal\venv\lib\site-packages\kombu\utils\functional.py", line 312, in retry_over_time
    return fun(*args, **kwargs)
  File "D:\PythonStudy\News_Portal\venv\lib\site-packages\celery\backends\redis.py", line 106, in _reconnect_pubsub
    metas = self.backend.client.mget(self.subscribed_to)
  File "D:\PythonStudy\News_Portal\venv\lib\site-packages\redis\commands\core.py", line 1404, in mget
    return self.execute_command("MGET", *args, **options)
  File "D:\PythonStudy\News_Portal\venv\lib\site-packages\redis\client.py", line 1173, in execute_command
    conn = self.connection or pool.get_connection(command_name, **options)
  File "D:\PythonStudy\News_Portal\venv\lib\site-packages\redis\connection.py", line 1370, in get_connection
    connection.connect()
  File "D:\PythonStudy\News_Portal\venv\lib\site-packages\redis\connection.py", line 613, in connect
    raise ConnectionError(self._error_message(e))
redis.exceptions.ConnectionError: Error 10061 connecting to localhost:6379. Подключение не установлено, т.к. конечный компьютер отверг запрос на подключение.

The above exception was the direct cause of the following exception:

Traceback (most recent call last):
  File "D:\PythonStudy\News_Portal\venv\lib\site-packages\django\core\handlers\exception.py", line 47, in inner
    response = get_response(request)
  File "D:\PythonStudy\News_Portal\venv\lib\site-packages\django\core\handlers\base.py", line 181, in _get_response
    response = wrapped_callback(request, *callback_args, **callback_kwargs)
  File "D:\PythonStudy\News_Portal\venv\lib\site-packages\django\contrib\admin\options.py", line 622, in wrapper
    return self.admin_site.admin_view(view)(*args, **kwargs)
  File "D:\PythonStudy\News_Portal\venv\lib\site-packages\django\utils\decorators.py", line 130, in _wrapped_view
    response = view_func(request, *args, **kwargs)
  File "D:\PythonStudy\News_Portal\venv\lib\site-packages\django\views\decorators\cache.py", line 57, in _wrapped_view_func
    response = view_func(request, *args, **kwargs)
  File "D:\PythonStudy\News_Portal\venv\lib\site-packages\django\contrib\admin\sites.py", line 236, in inner
    return view(request, *args, **kwargs)
  File "D:\PythonStudy\News_Portal\venv\lib\site-packages\django\contrib\admin\options.py", line 1673, in change_view
    return self.changeform_view(request, object_id, form_url, extra_context)
  File "D:\PythonStudy\News_Portal\venv\lib\site-packages\django\utils\decorators.py", line 43, in _wrapper
    return bound_method(*args, **kwargs)
  File "D:\PythonStudy\News_Portal\venv\lib\site-packages\django\utils\decorators.py", line 130, in _wrapped_view
    response = view_func(request, *args, **kwargs)
  File "D:\PythonStudy\News_Portal\venv\lib\site-packages\django\contrib\admin\options.py", line 1549, in changeform_view
    return self._changeform_view(request, object_id, form_url, extra_context)
  File "D:\PythonStudy\News_Portal\venv\lib\site-packages\django\contrib\admin\options.py", line 1599, in _changeform_view
    self.save_model(request, new_object, form, not add)
  File "D:\PythonStudy\News_Portal\venv\lib\site-packages\django\contrib\admin\options.py", line 1108, in save_model
    obj.save()
  File "D:\PythonStudy\News_Portal\news_portal\newsportal\models.py", line 71, in save
    super().save(*args, **kwargs)
  File "D:\PythonStudy\News_Portal\venv\lib\site-packages\django\db\models\base.py", line 743, in save
    self.save_base(using=using, force_insert=force_insert,
  File "D:\PythonStudy\News_Portal\venv\lib\site-packages\django\db\models\base.py", line 791, in save_base
    post_save.send(
  File "D:\PythonStudy\News_Portal\venv\lib\site-packages\django\dispatch\dispatcher.py", line 170, in send
    return [
  File "D:\PythonStudy\News_Portal\venv\lib\site-packages\django\dispatch\dispatcher.py", line 171, in <listcomp>
    (receiver, receiver(signal=self, sender=sender, **named))
  File "D:\PythonStudy\News_Portal\news_portal\newsportal\signals.py", line 21, in notify_update_post
    new_posts.delay(pk, nw)
  File "D:\PythonStudy\News_Portal\venv\lib\site-packages\celery\app\task.py", line 425, in delay
    return self.apply_async(args, kwargs)
  File "D:\PythonStudy\News_Portal\venv\lib\site-packages\celery\app\task.py", line 575, in apply_async
    return app.send_task(
  File "D:\PythonStudy\News_Portal\venv\lib\site-packages\celery\app\base.py", line 788, in send_task
    amqp.send_task_message(P, name, message, **options)
  File "C:\Users\kotko\AppData\Local\Programs\Python\Python39\lib\contextlib.py", line 135, in __exit__
    self.gen.throw(type, value, traceback)
  File "D:\PythonStudy\News_Portal\venv\lib\site-packages\kombu\connection.py", line 450, in _reraise_as_library_errors
    raise ConnectionError(str(exc)) from exc
kombu.exceptions.OperationalError: Error 10061 connecting to localhost:6379. Подключение не установлено, т.к. конечный компьютер отверг запрос на подключение.
2022-05-16 17:27:59,967 : ERROR - "POST /admin/newsportal/post/328/change/ HTTP/1.1" 500 329675 - D:\PythonStudy\News_Portal\venv\lib\site-packages\django\core\servers\basehttp.py - None
2022-05-16 17:32:31,935 : ERROR - Internal Server Error: /admin/newsportal/post/328/change/ - D:\PythonStudy\News_Portal\venv\lib\site-packages\django\utils\log.py - (<class 'kombu.exceptions.OperationalError'>, OperationalError('Error 10061 connecting to localhost:6379. Подключение не установлено, т.к. конечный компьютер отверг запрос на подключение.'), <traceback object at 0x0000022B0997F2C0>)
Traceback (most recent call last):
  File "D:\PythonStudy\News_Portal\venv\lib\site-packages\redis\connection.py", line 607, in connect
    sock = self.retry.call_with_retry(
  File "D:\PythonStudy\News_Portal\venv\lib\site-packages\redis\retry.py", line 45, in call_with_retry
    return do()
  File "D:\PythonStudy\News_Portal\venv\lib\site-packages\redis\connection.py", line 608, in <lambda>
    lambda: self._connect(), lambda error: self.disconnect(error)
  File "D:\PythonStudy\News_Portal\venv\lib\site-packages\redis\connection.py", line 673, in _connect
    raise err
  File "D:\PythonStudy\News_Portal\venv\lib\site-packages\redis\connection.py", line 661, in _connect
    sock.connect(socket_address)
ConnectionRefusedError: [WinError 10061] Подключение не установлено, т.к. конечный компьютер отверг запрос на подключение

During handling of the above exception, another exception occurred:

Traceback (most recent call last):
  File "D:\PythonStudy\News_Portal\venv\lib\site-packages\celery\backends\redis.py", line 119, in reconnect_on_error
    yield
  File "D:\PythonStudy\News_Portal\venv\lib\site-packages\celery\backends\redis.py", line 169, in _consume_from
    self._pubsub.subscribe(key)
  File "D:\PythonStudy\News_Portal\venv\lib\site-packages\redis\client.py", line 1530, in subscribe
    ret_val = self.execute_command("SUBSCRIBE", *new_channels.keys())
  File "D:\PythonStudy\News_Portal\venv\lib\site-packages\redis\client.py", line 1371, in execute_command
    self.connection = self.connection_pool.get_connection(
  File "D:\PythonStudy\News_Portal\venv\lib\site-packages\redis\connection.py", line 1370, in get_connection
    connection.connect()
  File "D:\PythonStudy\News_Portal\venv\lib\site-packages\redis\connection.py", line 613, in connect
    raise ConnectionError(self._error_message(e))
redis.exceptions.ConnectionError: Error 10061 connecting to localhost:6379. Подключение не установлено, т.к. конечный компьютер отверг запрос на подключение.

During handling of the above exception, another exception occurred:

Traceback (most recent call last):
  File "D:\PythonStudy\News_Portal\venv\lib\site-packages\redis\connection.py", line 607, in connect
    sock = self.retry.call_with_retry(
  File "D:\PythonStudy\News_Portal\venv\lib\site-packages\redis\retry.py", line 45, in call_with_retry
    return do()
  File "D:\PythonStudy\News_Portal\venv\lib\site-packages\redis\connection.py", line 608, in <lambda>
    lambda: self._connect(), lambda error: self.disconnect(error)
  File "D:\PythonStudy\News_Portal\venv\lib\site-packages\redis\connection.py", line 673, in _connect
    raise err
  File "D:\PythonStudy\News_Portal\venv\lib\site-packages\redis\connection.py", line 661, in _connect
    sock.connect(socket_address)
ConnectionRefusedError: [WinError 10061] Подключение не установлено, т.к. конечный компьютер отверг запрос на подключение

During handling of the above exception, another exception occurred:

Traceback (most recent call last):
  File "D:\PythonStudy\News_Portal\venv\lib\site-packages\kombu\connection.py", line 446, in _reraise_as_library_errors
    yield
  File "D:\PythonStudy\News_Portal\venv\lib\site-packages\celery\app\base.py", line 787, in send_task
    self.backend.on_task_call(P, task_id)
  File "D:\PythonStudy\News_Portal\venv\lib\site-packages\celery\backends\redis.py", line 365, in on_task_call
    self.result_consumer.consume_from(task_id)
  File "D:\PythonStudy\News_Portal\venv\lib\site-packages\celery\backends\redis.py", line 161, in consume_from
    return self.start(task_id)
  File "D:\PythonStudy\News_Portal\venv\lib\site-packages\celery\backends\redis.py", line 139, in start
    self._consume_from(initial_task_id)
  File "D:\PythonStudy\News_Portal\venv\lib\site-packages\celery\backends\redis.py", line 169, in _consume_from
    self._pubsub.subscribe(key)
  File "C:\Users\kotko\AppData\Local\Programs\Python\Python39\lib\contextlib.py", line 135, in __exit__
    self.gen.throw(type, value, traceback)
  File "D:\PythonStudy\News_Portal\venv\lib\site-packages\celery\backends\redis.py", line 122, in reconnect_on_error
    self._ensure(self._reconnect_pubsub, ())
  File "D:\PythonStudy\News_Portal\venv\lib\site-packages\celery\backends\redis.py", line 376, in ensure
    return retry_over_time(
  File "D:\PythonStudy\News_Portal\venv\lib\site-packages\kombu\utils\functional.py", line 312, in retry_over_time
    return fun(*args, **kwargs)
  File "D:\PythonStudy\News_Portal\venv\lib\site-packages\celery\backends\redis.py", line 106, in _reconnect_pubsub
    metas = self.backend.client.mget(self.subscribed_to)
  File "D:\PythonStudy\News_Portal\venv\lib\site-packages\redis\commands\core.py", line 1404, in mget
    return self.execute_command("MGET", *args, **options)
  File "D:\PythonStudy\News_Portal\venv\lib\site-packages\redis\client.py", line 1173, in execute_command
    conn = self.connection or pool.get_connection(command_name, **options)
  File "D:\PythonStudy\News_Portal\venv\lib\site-packages\redis\connection.py", line 1370, in get_connection
    connection.connect()
  File "D:\PythonStudy\News_Portal\venv\lib\site-packages\redis\connection.py", line 613, in connect
    raise ConnectionError(self._error_message(e))
redis.exceptions.ConnectionError: Error 10061 connecting to localhost:6379. Подключение не установлено, т.к. конечный компьютер отверг запрос на подключение.

The above exception was the direct cause of the following exception:

Traceback (most recent call last):
  File "D:\PythonStudy\News_Portal\venv\lib\site-packages\django\core\handlers\exception.py", line 47, in inner
    response = get_response(request)
  File "D:\PythonStudy\News_Portal\venv\lib\site-packages\django\core\handlers\base.py", line 181, in _get_response
    response = wrapped_callback(request, *callback_args, **callback_kwargs)
  File "D:\PythonStudy\News_Portal\venv\lib\site-packages\django\contrib\admin\options.py", line 622, in wrapper
    return self.admin_site.admin_view(view)(*args, **kwargs)
  File "D:\PythonStudy\News_Portal\venv\lib\site-packages\django\utils\decorators.py", line 130, in _wrapped_view
    response = view_func(request, *args, **kwargs)
  File "D:\PythonStudy\News_Portal\venv\lib\site-packages\django\views\decorators\cache.py", line 57, in _wrapped_view_func
    response = view_func(request, *args, **kwargs)
  File "D:\PythonStudy\News_Portal\venv\lib\site-packages\django\contrib\admin\sites.py", line 236, in inner
    return view(request, *args, **kwargs)
  File "D:\PythonStudy\News_Portal\venv\lib\site-packages\django\contrib\admin\options.py", line 1673, in change_view
    return self.changeform_view(request, object_id, form_url, extra_context)
  File "D:\PythonStudy\News_Portal\venv\lib\site-packages\django\utils\decorators.py", line 43, in _wrapper
    return bound_method(*args, **kwargs)
  File "D:\PythonStudy\News_Portal\venv\lib\site-packages\django\utils\decorators.py", line 130, in _wrapped_view
    response = view_func(request, *args, **kwargs)
  File "D:\PythonStudy\News_Portal\venv\lib\site-packages\django\contrib\admin\options.py", line 1549, in changeform_view
    return self._changeform_view(request, object_id, form_url, extra_context)
  File "D:\PythonStudy\News_Portal\venv\lib\site-packages\django\contrib\admin\options.py", line 1599, in _changeform_view
    self.save_model(request, new_object, form, not add)
  File "D:\PythonStudy\News_Portal\venv\lib\site-packages\django\contrib\admin\options.py", line 1108, in save_model
    obj.save()
  File "D:\PythonStudy\News_Portal\news_portal\newsportal\models.py", line 71, in save
    super().save(*args, **kwargs)
  File "D:\PythonStudy\News_Portal\venv\lib\site-packages\django\db\models\base.py", line 743, in save
    self.save_base(using=using, force_insert=force_insert,
  File "D:\PythonStudy\News_Portal\venv\lib\site-packages\django\db\models\base.py", line 791, in save_base
    post_save.send(
  File "D:\PythonStudy\News_Portal\venv\lib\site-packages\django\dispatch\dispatcher.py", line 170, in send
    return [
  File "D:\PythonStudy\News_Portal\venv\lib\site-packages\django\dispatch\dispatcher.py", line 171, in <listcomp>
    (receiver, receiver(signal=self, sender=sender, **named))
  File "D:\PythonStudy\News_Portal\news_portal\newsportal\signals.py", line 21, in notify_update_post
    new_posts.delay(pk, nw)
  File "D:\PythonStudy\News_Portal\venv\lib\site-packages\celery\app\task.py", line 425, in delay
    return self.apply_async(args, kwargs)
  File "D:\PythonStudy\News_Portal\venv\lib\site-packages\celery\app\task.py", line 575, in apply_async
    return app.send_task(
  File "D:\PythonStudy\News_Portal\venv\lib\site-packages\celery\app\base.py", line 788, in send_task
    amqp.send_task_message(P, name, message, **options)
  File "C:\Users\kotko\AppData\Local\Programs\Python\Python39\lib\contextlib.py", line 135, in __exit__
    self.gen.throw(type, value, traceback)
  File "D:\PythonStudy\News_Portal\venv\lib\site-packages\kombu\connection.py", line 450, in _reraise_as_library_errors
    raise ConnectionError(str(exc)) from exc
kombu.exceptions.OperationalError: Error 10061 connecting to localhost:6379. Подключение не установлено, т.к. конечный компьютер отверг запрос на подключение.
2022-05-16 17:32:31,938 : ERROR - "POST /admin/newsportal/post/328/change/ HTTP/1.1" 500 329354 - D:\PythonStudy\News_Portal\venv\lib\site-packages\django\core\servers\basehttp.py - None
2022-05-16 20:31:00,214 : ERROR - Internal Server Error: / - D:\PythonStudy\News_Portal\venv\lib\site-packages\django\utils\log.py - (<class 'AttributeError'>, AttributeError("'dict' object has no attribute 'status_code'"), <traceback object at 0x000001A157B0F200>)
Traceback (most recent call last):
  File "D:\PythonStudy\News_Portal\venv\lib\site-packages\django\core\handlers\exception.py", line 47, in inner
    response = get_response(request)
  File "D:\PythonStudy\News_Portal\venv\lib\site-packages\django\utils\deprecation.py", line 128, in __call__
    response = self.process_response(request, response)
  File "D:\PythonStudy\News_Portal\venv\lib\site-packages\django\contrib\flatpages\middleware.py", line 9, in process_response
    if response.status_code != 404:
AttributeError: 'dict' object has no attribute 'status_code'
2022-05-16 20:31:00,233 : ERROR - "GET / HTTP/1.1" 500 78235 - D:\PythonStudy\News_Portal\venv\lib\site-packages\django\core\servers\basehttp.py - None
2022-05-16 20:41:42,092 : ERROR - Internal Server Error: /news/search/ - D:\PythonStudy\News_Portal\venv\lib\site-packages\django\utils\log.py - (<class 'django.template.exceptions.TemplateSyntaxError'>, TemplateSyntaxError("Invalid block tag on line 65: 'get_current_timezone'. Did you forget to register or load this tag?"), <traceback object at 0x000001E786652740>)
Traceback (most recent call last):
  File "D:\PythonStudy\News_Portal\venv\lib\site-packages\django\template\base.py", line 500, in parse
    compile_func = self.tags[command]
KeyError: 'get_current_timezone'

During handling of the above exception, another exception occurred:

Traceback (most recent call last):
  File "D:\PythonStudy\News_Portal\venv\lib\site-packages\django\core\handlers\exception.py", line 47, in inner
    response = get_response(request)
  File "D:\PythonStudy\News_Portal\venv\lib\site-packages\django\core\handlers\base.py", line 204, in _get_response
    response = response.render()
  File "D:\PythonStudy\News_Portal\venv\lib\site-packages\django\template\response.py", line 105, in render
    self.content = self.rendered_content
  File "D:\PythonStudy\News_Portal\venv\lib\site-packages\django\template\response.py", line 83, in rendered_content
    return template.render(context, self._request)
  File "D:\PythonStudy\News_Portal\venv\lib\site-packages\django\template\backends\django.py", line 61, in render
    return self.template.render(context)
  File "D:\PythonStudy\News_Portal\venv\lib\site-packages\django\template\base.py", line 176, in render
    return self._render(context)
  File "D:\PythonStudy\News_Portal\venv\lib\site-packages\django\template\base.py", line 168, in _render
    return self.nodelist.render(context)
  File "D:\PythonStudy\News_Portal\venv\lib\site-packages\django\template\base.py", line 977, in render
    return SafeString(''.join([
  File "D:\PythonStudy\News_Portal\venv\lib\site-packages\django\template\base.py", line 978, in <listcomp>
    node.render_annotated(context) for node in self
  File "D:\PythonStudy\News_Portal\venv\lib\site-packages\django\template\base.py", line 938, in render_annotated
    return self.render(context)
  File "D:\PythonStudy\News_Portal\venv\lib\site-packages\django\template\loader_tags.py", line 130, in render
    compiled_parent = self.get_parent(context)
  File "D:\PythonStudy\News_Portal\venv\lib\site-packages\django\template\loader_tags.py", line 127, in get_parent
    return self.find_template(parent, context)
  File "D:\PythonStudy\News_Portal\venv\lib\site-packages\django\template\loader_tags.py", line 106, in find_template
    template, origin = context.template.engine.find_template(
  File "D:\PythonStudy\News_Portal\venv\lib\site-packages\django\template\engine.py", line 145, in find_template
    template = loader.get_template(name, skip=skip)
  File "D:\PythonStudy\News_Portal\venv\lib\site-packages\django\template\loaders\base.py", line 29, in get_template
    return Template(
  File "D:\PythonStudy\News_Portal\venv\lib\site-packages\django\template\base.py", line 155, in __init__
    self.nodelist = self.compile_nodelist()
  File "D:\PythonStudy\News_Portal\venv\lib\site-packages\django\template\base.py", line 199, in compile_nodelist
    return parser.parse()
  File "D:\PythonStudy\News_Portal\venv\lib\site-packages\django\template\base.py", line 502, in parse
    self.invalid_block_tag(token, command, parse_until)
  File "D:\PythonStudy\News_Portal\venv\lib\site-packages\django\template\base.py", line 561, in invalid_block_tag
    raise self.error(
django.template.exceptions.TemplateSyntaxError: Invalid block tag on line 65: 'get_current_timezone'. Did you forget to register or load this tag?
2022-05-16 20:41:42,096 : ERROR - "GET /news/search/?page=1 HTTP/1.1" 500 212770 - D:\PythonStudy\News_Portal\venv\lib\site-packages\django\core\servers\basehttp.py - None
